Workbook

Sheet Rolling Alpha
A1: Date | B1: MGGIX US | C1: ACWI | D1: Return MGGIX US, Rp | E1: Return ACWI, Rm | F1: Risk-free | G1: Fund Excess | H1: Benchmark Excess | I1: Alpha | J1: Beta
A2: 2018-01-31 | B2: ='MGGIX US_monthly'!B14 -> 24.86 | C2: ='MSCI ACWI Index_monthly'!B14 -> 260.0665 | F2: =(1+'Risk-free rate'!B14/100)^(1/12)-1 -> 0.0011674743
A3: 2018-02-28 | B3: ='MGGIX US_monthly'!B15 -> 24.37 | C3: ='MSCI ACWI Index_monthly'!B15 -> 249.14416 | D3: =('MGGIX US_monthly'!B15-'MGGIX US_monthly'!B14)/'MGGIX US_monthly'!B14 -> -0.019710378 | E3: =('MSCI ACWI Index_monthly'!B15-'MSCI ACWI Index_monthly'!B14)/'MSCI ACWI Index_monthly'!B14 -> -0.04199827 | F3: =(1+'Risk-free rate'!B15/100)^(1/12)-1 -> 0.0012990121 | G3: =D3-$F3 -> -0.02100939 | H3: =E3-$F3 -> -0.043297282
A4: 2018-03-30 | B4: ='MGGIX US_monthly'!B16 -> 24.22 | C4: ='MSCI ACWI Index_monthly'!B16 -> 243.81079 | D4: =('MGGIX US_monthly'!B16-'MGGIX US_monthly'!B15)/'MGGIX US_monthly'!B15 -> -0.0061551087 | E4: =('MSCI ACWI Index_monthly'!B16-'MSCI ACWI Index_monthly'!B15)/'MSCI ACWI Index_monthly'!B15 -> -0.021406743 | F4: =(1+'Risk-free rate'!B16/100)^(1/12)-1 -> 0.0014057469 | G4: =D4-$F4 -> -0.0075608556 | H4: =E4-$F4 -> -0.02281249
A5: 2018-04-30 | B5: ='MGGIX US_monthly'!B17 -> 24.62 | C5: ='MSCI ACWI Index_monthly'!B17 -> 246.13908 | D5: =('MGGIX US_monthly'!B17-'MGGIX US_monthly'!B16)/'MGGIX US_monthly'!B16 -> 0.016515277 | E5: =('MSCI ACWI Index_monthly'!B17-'MSCI ACWI Index_monthly'!B16)/'MSCI ACWI Index_monthly'!B16 -> 0.0095495651 | F5: =(1+'Risk-free rate'!B17/100)^(1/12)-1 -> 0.0014549669 | G5: =D5-$F5 -> 0.01506031 | H5: =E5-$F5 -> 0.0080945981
A6: 2018-05-31 | B6: ='MGGIX US_monthly'!B18 -> 26.11 | C6: ='MSCI ACWI Index_monthly'!B18 -> 246.44638 | D6: =('MGGIX US_monthly'!B18-'MGGIX US_monthly'!B17)/'MGGIX US_monthly'!B17 -> 0.060519903 | E6: =('MSCI ACWI Index_monthly'!B18-'MSCI ACWI Index_monthly'!B17)/'MSCI ACWI Index_monthly'!B17 -> 0.0012484852 | F6: =(1+'Risk-free rate'!B18/100)^(1/12)-1 -> 0.0015369412 | G6: =D6-$F6 -> 0.058982961 | H6: =E6-$F6 -> -0.00028845595
A7: 2018-06-29 | B7: ='MGGIX US_monthly'!B19 -> 25.82 | C7: ='MSCI ACWI Index_monthly'!B19 -> 245.11177 | D7: =('MGGIX US_monthly'!B19-'MGGIX US_monthly'!B18)/'MGGIX US_monthly'!B18 -> -0.011106856 | E7: =('MSCI ACWI Index_monthly'!B19-'MSCI ACWI Index_monthly'!B18)/'MSCI ACWI Index_monthly'!B18 -> -0.005415393 | F7: =(1+'Risk-free rate'!B19/100)^(1/12)-1 -> 0.0015697102 | G7: =D7-$F7 -> -0.012676566 | H7: =E7-$F7 -> -0.0069851033
A8: 2018-07-31 | B8: ='MGGIX US_monthly'!B20 -> 25.35 | C8: ='MSCI ACWI Index_monthly'!B20 -> 252.50355 | D8: =('MGGIX US_monthly'!B20-'MGGIX US_monthly'!B19)/'MGGIX US_monthly'!B19 -> -0.018202943 | E8: =('MSCI ACWI Index_monthly'!B20-'MSCI ACWI Index_monthly'!B19)/'MSCI ACWI Index_monthly'!B19 -> 0.03015674 | F8: =(1+'Risk-free rate'!B20/100)^(1/12)-1 -> 0.0016188417 | G8: =D8-$F8 -> -0.019821785 | H8: =E8-$F8 -> 0.028537898
A9: 2018-08-31 | B9: ='MGGIX US_monthly'!B21 -> 25.72 | C9: ='MSCI ACWI Index_monthly'!B21 -> 254.48731 | D9: =('MGGIX US_monthly'!B21-'MGGIX US_monthly'!B20)/'MGGIX US_monthly'!B20 -> 0.014595661 | E9: =('MSCI ACWI Index_monthly'!B21-'MSCI ACWI Index_monthly'!B20)/'MSCI ACWI Index_monthly'!B20 -> 0.0078563847 | F9: =(1+'Risk-free rate'!B21/100)^(1/12)-1 -> 0.0016761283 | G9: =D9-$F9 -> 0.012919532 | H9: =E9-$F9 -> 0.0061802564
A10: 2018-09-28 | B10: ='MGGIX US_monthly'!B22 -> 25.39 | C10: ='MSCI ACWI Index_monthly'!B22 -> 255.59489 | D10: =('MGGIX US_monthly'!B22-'MGGIX US_monthly'!B21)/'MGGIX US_monthly'!B21 -> -0.012830482 | E10: =('MSCI ACWI Index_monthly'!B22-'MSCI ACWI Index_monthly'!B21)/'MSCI ACWI Index_monthly'!B21 -> 0.0043522052 | F10: =(1+'Risk-free rate'!B22/100)^(1/12)-1 -> 0.0017579038 | G10: =D10-$F10 -> -0.014588386 | H10: =E10-$F10 -> 0.0025943014
A11: 2018-10-31 | B11: ='MGGIX US_monthly'!B23 -> 22.58 | C11: ='MSCI ACWI Index_monthly'!B23 -> 236.44088 | D11: =('MGGIX US_monthly'!B23-'MGGIX US_monthly'!B22)/'MGGIX US_monthly'!B22 -> -0.11067349 | E11: =('MSCI ACWI Index_monthly'!B23-'MSCI ACWI Index_monthly'!B22)/'MSCI ACWI Index_monthly'!B22 -> -0.074938935 | F11: =(1+'Risk-free rate'!B23/100)^(1/12)-1 -> 0.0018559375 | G11: =D11-$F11 -> -0.11252943 | H11: =E11-$F11 -> -0.076794873
A12: 2018-11-30 | B12: ='MGGIX US_monthly'!B24 -> 22.94 | C12: ='MSCI ACWI Index_monthly'!B24 -> 239.89893 | D12: =('MGGIX US_monthly'!B24-'MGGIX US_monthly'!B23)/'MGGIX US_monthly'!B23 -> 0.015943313 | E12: =('MSCI ACWI Index_monthly'!B24-'MSCI ACWI Index_monthly'!B23)/'MSCI ACWI Index_monthly'!B23 -> 0.014625419 | F12: =(1+'Risk-free rate'!B24/100)^(1/12)-1 -> 0.0019212348 | G12: =D12-$F12 -> 0.014022078 | H12: =E12-$F12 -> 0.012704184
A13: 2018-12-31 | B13: ='MGGIX US_monthly'!B25 -> 21.5 | C13: ='MSCI ACWI Index_monthly'!B25 -> 223.00178 | D13: =('MGGIX US_monthly'!B25-'MGGIX US_monthly'!B24)/'MGGIX US_monthly'!B24 -> -0.06277245 | E13: =('MSCI ACWI Index_monthly'!B25-'MSCI ACWI Index_monthly'!B24)/'MSCI ACWI Index_monthly'!B24 -> -0.07043447 | F13: =(1+'Risk-free rate'!B25/100)^(1/12)-1 -> 0.0019538659 | G13: =D13-$F13 -> -0.064726316 | H13: =E13-$F13 -> -0.072388336
A14: ='MGGIX US_monthly'!A26 -> 2019-01-31 | B14: ='MGGIX US_monthly'!B26 -> 23.76 | C14: ='MSCI ACWI Index_monthly'!B26 -> 240.6099 | D14: =('MGGIX US_monthly'!B26-'MGGIX US_monthly'!B25)/'MGGIX US_monthly'!B25 -> 0.10511629 | E14: =('MSCI ACWI Index_monthly'!B26-'MSCI ACWI Index_monthly'!B25)/'MSCI ACWI Index_monthly'!B25 -> 0.078959577 | F14: =(1+'Risk-free rate'!B26/100)^(1/12)-1 -> 0.0019538659 | G14: =D14-$F14 -> 0.10316242 | H14: =E14-$F14 -> 0.077005712 | I14: =((1+INDEX(LINEST(G3:G14,H3:H14,TRUE,TRUE),1,2))^12)-1 -> 0.047968507 | J14: =INDEX(LINEST(G3:G14, H3:H14, TRUE, TRUE), 1, 1) -> 1.0944654
A15: ='MGGIX US_monthly'!A27 -> 2019-02-28 | B15: ='MGGIX US_monthly'!B27 -> 24.48 | C15: ='MSCI ACWI Index_monthly'!B27 -> 247.04553 | D15: =('MGGIX US_monthly'!B27-'MGGIX US_monthly'!B26)/'MGGIX US_monthly'!B26 -> 0.030303001 | E15: =('MSCI ACWI Index_monthly'!B27-'MSCI ACWI Index_monthly'!B26)/'MSCI ACWI Index_monthly'!B26 -> 0.026747149 | F15: =(1+'Risk-free rate'!B27/100)^(1/12)-1 -> 0.0019701771 | G15: =D15-$F15 -> 0.028332824 | H15: =E15-$F15 -> 0.024776972 | I15: =((1+INDEX(LINEST(G4:G15,H4:H15,TRUE,TRUE),1,2))^12)-1 -> 0.022887455 | J15: =INDEX(LINEST(G4:G15, H4:H15, TRUE, TRUE), 1, 1) -> 1.1392849
A16: ='MGGIX US_monthly'!A28 -> 2019-03-29 | B16: ='MGGIX US_monthly'!B28 -> 25.469999 | C16: ='MSCI ACWI Index_monthly'!B28 -> 250.15238 | D16: =('MGGIX US_monthly'!B28-'MGGIX US_monthly'!B27)/'MGGIX US_monthly'!B27 -> 0.040441168 | E16: =('MSCI ACWI Index_monthly'!B28-'MSCI ACWI Index_monthly'!B27)/'MSCI ACWI Index_monthly'!B27 -> 0.012576002 | F16: =(1+'Risk-free rate'!B28/100)^(1/12)-1 -> 0.0019783315 | G16: =D16-$F16 -> 0.038462836 | H16: =E16-$F16 -> 0.01059767 | I16: =((1+INDEX(LINEST(G5:G16,H5:H16,TRUE,TRUE),1,2))^12)-1 -> 0.030565006 | J16: =INDEX(LINEST(G5:G16, H5:H16, TRUE, TRUE), 1, 1) -> 1.1724749
A17: ='MGGIX US_monthly'!A29 -> 2019-04-30 | B17: ='MGGIX US_monthly'!B29 -> 26.75 | C17: ='MSCI ACWI Index_monthly'!B29 -> 258.59893 | D17: =('MGGIX US_monthly'!B29-'MGGIX US_monthly'!B28)/'MGGIX US_monthly'!B28 -> 0.050255231 | E17: =('MSCI ACWI Index_monthly'!B29-'MSCI ACWI Index_monthly'!B28)/'MSCI ACWI Index_monthly'!B28 -> 0.033765628 | F17: =(1+'Risk-free rate'!B29/100)^(1/12)-1 -> 0.0019620218 | G17: =D17-$F17 -> 0.048293209 | H17: =E17-$F17 -> 0.031803606 | I17: =((1+INDEX(LINEST(G6:G17,H6:H17,TRUE,TRUE),1,2))^12)-1 -> 0.03571527 | J17: =INDEX(LINEST(G6:G17, H6:H17, TRUE, TRUE), 1, 1) -> 1.1840279
A18: ='MGGIX US_monthly'!A30 -> 2019-05-31 | B18: ='MGGIX US_monthly'!B30 -> 25.51 | C18: ='MSCI ACWI Index_monthly'!B30 -> 243.25909 | D18: =('MGGIX US_monthly'!B30-'MGGIX US_monthly'!B29)/'MGGIX US_monthly'!B29 -> -0.046355132 | E18: =('MSCI ACWI Index_monthly'!B30-'MSCI ACWI Index_monthly'!B29)/'MSCI ACWI Index_monthly'!B29 -> -0.059319028 | F18: =(1+'Risk-free rate'!B30/100)^(1/12)-1 -> 0.0019375518 | G18: =D18-$F18 -> -0.048292683 | H18: =E18-$F18 -> -0.06125658 | I18: =((1+INDEX(LINEST(G7:G18,H7:H18,TRUE,TRUE),1,2))^12)-1 -> -0.0012796263 | J18: =INDEX(LINEST(G7:G18, H7:H18, TRUE, TRUE), 1, 1) -> 1.1264881
A19: ='MGGIX US_monthly'!A31 -> 2019-06-28 | B19: ='MGGIX US_monthly'!B31 -> 27.08 | C19: ='MSCI ACWI Index_monthly'!B31 -> 259.1876 | D19: =('MGGIX US_monthly'!B31-'MGGIX US_monthly'!B30)/'MGGIX US_monthly'!B30 -> 0.06154448 | E19: =('MSCI ACWI Index_monthly'!B31-'MSCI ACWI Index_monthly'!B30)/'MSCI ACWI Index_monthly'!B30 -> 0.065479612 | F19: =(1+'Risk-free rate'!B31/100)^(1/12)-1 -> 0.0017905934 | G19: =D19-$F19 -> 0.059753886 | H19: =E19-$F19 -> 0.063689019 | I19: =((1+INDEX(LINEST(G8:G19,H8:H19,TRUE,TRUE),1,2))^12)-1 -> -0.0071239207 | J19: =INDEX(LINEST(G8:G19, H8:H19, TRUE, TRUE), 1, 1) -> 1.0987495
A20: ='MGGIX US_monthly'!A32 -> 2019-07-31 | B20: ='MGGIX US_monthly'!B32 -> 26.870001 | C20: ='MSCI ACWI Index_monthly'!B32 -> 259.94706 | D20: =('MGGIX US_monthly'!B32-'MGGIX US_monthly'!B31)/'MGGIX US_monthly'!B31 -> -0.0077547668 | E20: =('MSCI ACWI Index_monthly'!B32-'MSCI ACWI Index_monthly'!B31)/'MSCI ACWI Index_monthly'!B31 -> 0.0029301517 | F20: =(1+'Risk-free rate'!B32/100)^(1/12)-1 -> 0.0017333788 | G20: =D20-$F20 -> -0.0094881456 | H20: =E20-$F20 -> 0.0011967729 | I20: =((1+INDEX(LINEST(G9:G20,H9:H20,TRUE,TRUE),1,2))^12)-1 -> 0.032683369 | J20: =INDEX(LINEST(G9:G20, H9:H20, TRUE, TRUE), 1, 1) -> 1.1496546
A21: ='MGGIX US_monthly'!A33 -> 2019-08-30 | B21: ='MGGIX US_monthly'!B33 -> 26.549999 | C21: ='MSCI ACWI Index_monthly'!B33 -> 253.78052 | D21: =('MGGIX US_monthly'!B33-'MGGIX US_monthly'!B32)/'MGGIX US_monthly'!B32 -> -0.011909252 | E21: =('MSCI ACWI Index_monthly'!B33-'MSCI ACWI Index_monthly'!B32)/'MSCI ACWI Index_monthly'!B32 -> -0.023722299 | F21: =(1+'Risk-free rate'!B33/100)^(1/12)-1 -> 0.001610655 | G21: =D21-$F21 -> -0.013519907 | H21: =E21-$F21 -> -0.025332954 | I21: =((1+INDEX(LINEST(G10:G21,H10:H21,TRUE,TRUE),1,2))^12)-1 -> 0.042665554 | J21: =INDEX(LINEST(G10:G21, H10:H21, TRUE, TRUE), 1, 1) -> 1.1373485
A22: ='MGGIX US_monthly'!A34 -> 2019-09-30 | B22: ='MGGIX US_monthly'!B34 -> 26.129999 | C22: ='MSCI ACWI Index_monthly'!B34 -> 259.12045 | D22: =('MGGIX US_monthly'!B34-'MGGIX US_monthly'!B33)/'MGGIX US_monthly'!B33 -> -0.015819212 | E22: =('MSCI ACWI Index_monthly'!B34-'MSCI ACWI Index_monthly'!B33)/'MSCI ACWI Index_monthly'!B33 -> 0.021041552 | F22: =(1+'Risk-free rate'!B34/100)^(1/12)-1 -> 0.0015615191 | G22: =D22-$F22 -> -0.017380731 | H22: =E22-$F22 -> 0.019480033 | I22: =((1+INDEX(LINEST(G11:G22,H11:H22,TRUE,TRUE),1,2))^12)-1 -> 0.020193028 | J22: =INDEX(LINEST(G11:G22, H11:H22, TRUE, TRUE), 1, 1) -> 1.1095196
A23: ='MGGIX US_monthly'!A35 -> 2019-10-31 | B23: ='MGGIX US_monthly'!B35 -> 27.059999 | C23: ='MSCI ACWI Index_monthly'!B35 -> 266.21225 | D23: =('MGGIX US_monthly'!B35-'MGGIX US_monthly'!B34)/'MGGIX US_monthly'!B34 -> 0.035591287 | E23: =('MSCI ACWI Index_monthly'!B35-'MSCI ACWI Index_monthly'!B34)/'MSCI ACWI Index_monthly'!B34 -> 0.027368719 | F23: =(1+'Risk-free rate'!B35/100)^(1/12)-1 -> 0.0013647099 | G23: =D23-$F23 -> 0.034226577 | H23: =E23-$F23 -> 0.026004009 | I23: =((1+INDEX(LINEST(G12:G23,H12:H23,TRUE,TRUE),1,2))^12)-1 -> 0.066827606 | J23: =INDEX(LINEST(G12:G23, H12:H23, TRUE, TRUE), 1, 1) -> 0.99724673
A24: ='MGGIX US_monthly'!A36 -> 2019-11-29 | B24: ='MGGIX US_monthly'!B36 -> 28.42 | C24: ='MSCI ACWI Index_monthly'!B36 -> 272.71088 | D24: =('MGGIX US_monthly'!B36-'MGGIX US_monthly'!B35)/'MGGIX US_monthly'!B35 -> 0.050258708 | E24: =('MSCI ACWI Index_monthly'!B36-'MSCI ACWI Index_monthly'!B35)/'MSCI ACWI Index_monthly'!B35 -> 0.024411461 | F24: =(1+'Risk-free rate'!B36/100)^(1/12)-1 -> 0.0012743633 | G24: =D24-$F24 -> 0.048984345 | H24: =E24-$F24 -> 0.023137098 | I24: =((1+INDEX(LINEST(G13:G24,H13:H24,TRUE,TRUE),1,2))^12)-1 -> 0.091506954 | J24: =INDEX(LINEST(G13:G24, H13:H24, TRUE, TRUE), 1, 1) -> 1.0102416
A25: ='MGGIX US_monthly'!A37 -> 2019-12-31 | B25: ='MGGIX US_monthly'!B37 -> 29.120001 | C25: ='MSCI ACWI Index_monthly'!B37 -> 282.31445 | D25: =('MGGIX US_monthly'!B37-'MGGIX US_monthly'!B36)/'MGGIX US_monthly'!B36 -> 0.024630569 | E25: =('MSCI ACWI Index_monthly'!B37-'MSCI ACWI Index_monthly'!B36)/'MSCI ACWI Index_monthly'!B36 -> 0.035215218 | F25: =(1+'Risk-free rate'!B37/100)^(1/12)-1 -> 0.0012743633 | G25: =D25-$F25 -> 0.023356205 | H25: =E25-$F25 -> 0.033940854 | I25: =((1+INDEX(LINEST(G14:G25,H14:H25,TRUE,TRUE),1,2))^12)-1 -> 0.073668351 | J25: =INDEX(LINEST(G14:G25, H14:H25, TRUE, TRUE), 1, 1) -> 0.99802943
... A85: ='MGGIX US_monthly'!A97 -> 2024-12-31 | B85: ='MGGIX US_monthly'!B97 -> 35.139999 | C85: ='MSCI ACWI Index_monthly'!B97 -> 455.98973 | D85: =('MGGIX US_monthly'!B97-'MGGIX US_monthly'!B96)/'MGGIX US_monthly'!B96 -> -0.10357146 | E85: =('MSCI ACWI Index_monthly'!B97-'MSCI ACWI Index_monthly'!B96)/'MSCI ACWI Index_monthly'!B96 -> -0.023671625 | F85: =(1+'Risk-free rate'!B97/100)^(1/12)-1 -> 0.0034905364 | G85: =D85-$F85 -> -0.107062 | H85: =E85-$F85 -> -0.027162162 | I85: =((1+INDEX(LINEST(G74:G85,H74:H85,TRUE,TRUE),1,2))^12)-1 -> -0.043901836 | J85: =INDEX(LINEST(G74:G85, H74:H85, TRUE, TRUE), 1, 1) -> 1.517966

Sheet Up-Down Scatter Plot
A1: Date | B1: Return MGGIX US, Rp | C1: Return ACWI, Rm | D1: Fund Geo-Mittel (Up) | E1: Benchmark Geo-Mittel (Up) | F1: UC Ratio | G1: Fund Geo-Mittel (Down) | H1: Benchmark Geo-Mittel (Down) | I1: DC Ratio | L1: Fund Geo-Mittel (Up) | M1: Benchmark Geo-Mittel (Up) | N1: UC Ratio | O1: Fund Geo-Mittel (Down) | P1: Benchmark Geo-Mittel (Down) | Q1: DC Ratio
A2: ='MGGIX US_monthly'!A2 -> 2017-01-31 | K2: pre-covid | L2: {=GEOMEAN(IF(C14:C38 > 0, 1 + B14:B38)) - 1} -> 0.030900646 | M2: {=GEOMEAN(IF(C14:C38 > 0, 1 + C14:C38)) - 1} -> 0.02640342 | N2: =(L2/M2)*100 -> 117.03274 | O2: {=GEOMEAN(IF(C14:C38<0,1+B14:B38))-1} -> -0.031867819 | P2: {=GEOMEAN(IF(C14:C38<0,1+C14:C38))-1} -> -0.03887126 | Q2: =(O2/P2)*100 -> 81.982985
A3: ='MGGIX US_monthly'!A3 -> 2017-02-28 | B3: =('MGGIX US_monthly'!B3-'MGGIX US_monthly'!B2)/'MGGIX US_monthly'!B2 -> 0.042944785 | C3: =('MSCI ACWI Index_monthly'!B3-'MSCI ACWI Index_monthly'!B2)/'MSCI ACWI Index_monthly'!B2 -> 0.028051298 | K3: during-covid | L3: {=GEOMEAN(IF(C26:C61 > 0, 1 + B26:B61)) - 1} -> 0.039674923 | M3: {=GEOMEAN(IF(C26:C61 > 0, 1 + C26:C61)) - 1} -> 0.039631873 | N3: =(L3/M3)*100 -> 100.10862 | O3: {=GEOMEAN(IF(C26:C61<0,1+B26:B61))-1} -> -0.032045174 | P3: {=GEOMEAN(IF(C26:C61<0,1+C26:C61))-1} -> -0.044386685 | Q3: =(O3/P3)*100 -> 72.195466
A4: ='MGGIX US_monthly'!A4 -> 2017-03-31 | B4: =('MGGIX US_monthly'!B4-'MGGIX US_monthly'!B3)/'MGGIX US_monthly'!B3 -> 0.050588235 | C4: =('MSCI ACWI Index_monthly'!B4-'MSCI ACWI Index_monthly'!B3)/'MSCI ACWI Index_monthly'!B3 -> 0.012233542 | K4: post-covid | L4: {=GEOMEAN(IF(C62:C97 > 0, 1 + B62:B97)) - 1} -> 0.047116889 | M4: {=GEOMEAN(IF(C62:C97 > 0, 1 + C62:C97)) - 1} -> 0.039138372 | N4: =(L4/M4)*100 -> 120.38541 | O4: {=GEOMEAN(IF(C62:C97<0,1+B62:B97))-1} -> -0.074509829 | P4: {=GEOMEAN(IF(C62:C97<0,1+C62:C97))-1} -> -0.042245272 | Q4: =(O4/P4)*100 -> 176.37436
A5: ='MGGIX US_monthly'!A5 -> 2017-04-28 | B5: =('MGGIX US_monthly'!B5-'MGGIX US_monthly'!B4)/'MGGIX US_monthly'!B4 -> 0.041993281 | C5: =('MSCI ACWI Index_monthly'!B5-'MSCI ACWI Index_monthly'!B4)/'MSCI ACWI Index_monthly'!B4 -> 0.015584667
A6: ='MGGIX US_monthly'!A6 -> 2017-05-31 | B6: =('MGGIX US_monthly'!B6-'MGGIX US_monthly'!B5)/'MGGIX US_monthly'!B5 -> 0.05265986 | C6: =('MSCI ACWI Index_monthly'!B6-'MSCI ACWI Index_monthly'!B5)/'MSCI ACWI Index_monthly'!B5 -> 0.022082854 | L6: MGGIX US and ACWI
A7: ='MGGIX US_monthly'!A7 -> 2017-06-30 | B7: =('MGGIX US_monthly'!B7-'MGGIX US_monthly'!B6)/'MGGIX US_monthly'!B6 -> -0.0035732517 | C7: =('MSCI ACWI Index_monthly'!B7-'MSCI ACWI Index_monthly'!B6)/'MSCI ACWI Index_monthly'!B6 -> 0.0045474443
A8: ='MGGIX US_monthly'!A8 -> 2017-07-31 | B8: =('MGGIX US_monthly'!B8-'MGGIX US_monthly'!B7)/'MGGIX US_monthly'!B7 -> 0.068135246 | C8: =('MSCI ACWI Index_monthly'!B8-'MSCI ACWI Index_monthly'!B7)/'MSCI ACWI Index_monthly'!B7 -> 0.027946674
A9: ='MGGIX US_monthly'!A9 -> 2017-08-31 | B9: =('MGGIX US_monthly'!B9-'MGGIX US_monthly'!B8)/'MGGIX US_monthly'!B8 -> 0.01822542 | C9: =('MSCI ACWI Index_monthly'!B9-'MSCI ACWI Index_monthly'!B8)/'MSCI ACWI Index_monthly'!B8 -> 0.0038311124
A10: ='MGGIX US_monthly'!A10 -> 2017-09-29 | B10: =('MGGIX US_monthly'!B10-'MGGIX US_monthly'!B9)/'MGGIX US_monthly'!B9 -> 0.017428168 | C10: =('MSCI ACWI Index_monthly'!B10-'MSCI ACWI Index_monthly'!B9)/'MSCI ACWI Index_monthly'!B9 -> 0.019320014
A11: ='MGGIX US_monthly'!A11 -> 2017-10-31 | B11: =('MGGIX US_monthly'!B11-'MGGIX US_monthly'!B10)/'MGGIX US_monthly'!B10 -> 0.027314815 | C11: =('MSCI ACWI Index_monthly'!B11-'MSCI ACWI Index_monthly'!B10)/'MSCI ACWI Index_monthly'!B10 -> 0.020765335
A12: ='MGGIX US_monthly'!A12 -> 2017-11-30 | B12: =('MGGIX US_monthly'!B12-'MGGIX US_monthly'!B11)/'MGGIX US_monthly'!B11 -> 0.01306895 | C12: =('MSCI ACWI Index_monthly'!B12-'MSCI ACWI Index_monthly'!B11)/'MSCI ACWI Index_monthly'!B11 -> 0.01935822
A13: ='MGGIX US_monthly'!A13 -> 2017-12-29 | B13: =('MGGIX US_monthly'!B13-'MGGIX US_monthly'!B12)/'MGGIX US_monthly'!B12 -> 0.020462633 | C13: =('MSCI ACWI Index_monthly'!B13-'MSCI ACWI Index_monthly'!B12)/'MSCI ACWI Index_monthly'!B12 -> 0.016121714
A14: ='MGGIX US_monthly'!A14 -> 2018-01-31 | B14: =('MGGIX US_monthly'!B14-'MGGIX US_monthly'!B13)/'MGGIX US_monthly'!B13 -> 0.0836966 | C14: =('MSCI ACWI Index_monthly'!B14-'MSCI ACWI Index_monthly'!B13)/'MSCI ACWI Index_monthly'!B13 -> 0.056416607
A15: ='MGGIX US_monthly'!A15 -> 2018-02-28 | B15: =('MGGIX US_monthly'!B15-'MGGIX US_monthly'!B14)/'MGGIX US_monthly'!B14 -> -0.019710378 | C15: =('MSCI ACWI Index_monthly'!B15-'MSCI ACWI Index_monthly'!B14)/'MSCI ACWI Index_monthly'!B14 -> -0.04199827
A16: ='MGGIX US_monthly'!A16 -> 2018-03-30 | B16: =('MGGIX US_monthly'!B16-'MGGIX US_monthly'!B15)/'MGGIX US_monthly'!B15 -> -0.0061551087 | C16: =('MSCI ACWI Index_monthly'!B16-'MSCI ACWI Index_monthly'!B15)/'MSCI ACWI Index_monthly'!B15 -> -0.021406743
A17: ='MGGIX US_monthly'!A17 -> 2018-04-30 | B17: =('MGGIX US_monthly'!B17-'MGGIX US_monthly'!B16)/'MGGIX US_monthly'!B16 -> 0.016515277 | C17: =('MSCI ACWI Index_monthly'!B17-'MSCI ACWI Index_monthly'!B16)/'MSCI ACWI Index_monthly'!B16 -> 0.0095495651
A18: ='MGGIX US_monthly'!A18 -> 2018-05-31 | B18: =('MGGIX US_monthly'!B18-'MGGIX US_monthly'!B17)/'MGGIX US_monthly'!B17 -> 0.060519903 | C18: =('MSCI ACWI Index_monthly'!B18-'MSCI ACWI Index_monthly'!B17)/'MSCI ACWI Index_monthly'!B17 -> 0.0012484852
... A36: ='MGGIX US_monthly'!A36 -> 2019-11-29 | B36: =('MGGIX US_monthly'!B36-'MGGIX US_monthly'!B35)/'MGGIX US_monthly'!B35 -> 0.050258708 | C36: =('MSCI ACWI Index_monthly'!B36-'MSCI ACWI Index_monthly'!B35)/'MSCI ACWI Index_monthly'!B35 -> 0.024411461
A37: ='MGGIX US_monthly'!A37 -> 2019-12-31 | B37: =('MGGIX US_monthly'!B37-'MGGIX US_monthly'!B36)/'MGGIX US_monthly'!B36 -> 0.024630569 | C37: =('MSCI ACWI Index_monthly'!B37-'MSCI ACWI Index_monthly'!B36)/'MSCI ACWI Index_monthly'!B36 -> 0.035215218 | D37: {=GEOMEAN(IF(C2:C37>0,1+B2:B37))-1} -> 0.031156777 | E37: {=GEOMEAN(IF(C2:C37>0,1+C2:C37))-1} -> 0.022789558 | F37: =(D37/E37)*100 -> 136.71514 | G37: {=GEOMEAN(IF(C2:C37<0,1+B2:B37))-1} -> -0.039047903 | H37: {=GEOMEAN(IF(C2:C37<0,1+C2:C37))-1} -> -0.042781877 | I37: =(G37/H37)*100 -> 91.272065
A38: ='MGGIX US_monthly'!A38 -> 2020-01-31 | B38: =('MGGIX US_monthly'!B38-'MGGIX US_monthly'!B37)/'MGGIX US_monthly'!B37 -> 0.019917579 | C38: =('MSCI ACWI Index_monthly'!B38-'MSCI ACWI Index_monthly'!B37)/'MSCI ACWI Index_monthly'!B37 -> -0.011045928 | D38: {=GEOMEAN(IF(C3:C38>0,1+B3:B38))-1} -> 0.031156777 | E38: {=GEOMEAN(IF(C3:C38>0,1+C3:C38))-1} -> 0.022789558 | F38: =(D38/E38)*100 -> 136.71514 | G38: {=GEOMEAN(IF(C3:C38<0,1+B3:B38))-1} -> -0.031867819 | H38: {=GEOMEAN(IF(C3:C38<0,1+C3:C38))-1} -> -0.03887126 | I38: =(G38/H38)*100 -> 81.982985
A39: ='MGGIX US_monthly'!A39 -> 2020-02-28 | B39: =('MGGIX US_monthly'!B39-'MGGIX US_monthly'!B38)/'MGGIX US_monthly'!B38 -> -0.044107789 | C39: =('MSCI ACWI Index_monthly'!B39-'MSCI ACWI Index_monthly'!B38)/'MSCI ACWI Index_monthly'!B38 -> -0.080769784 | D39: {=GEOMEAN(IF(C4:C39>0,1+B4:B39))-1} -> 0.030722752 | E39: {=GEOMEAN(IF(C4:C39>0,1+C4:C39))-1} -> 0.022595197 | F39: =(D39/E39)*100 -> 135.97027 | G39: {=GEOMEAN(IF(C4:C39<0,1+B4:B39))-1} -> -0.033235519 | H39: {=GEOMEAN(IF(C4:C39<0,1+C4:C39))-1} -> -0.043619405 | I39: =(G39/H39)*100 -> 76.194344
A40: ='MGGIX US_monthly'!A40 -> 2020-03-31 | B40: =('MGGIX US_monthly'!B40-'MGGIX US_monthly'!B39)/'MGGIX US_monthly'!B39 -> -0.094399449 | C40: =('MSCI ACWI Index_monthly'!B40-'MSCI ACWI Index_monthly'!B39)/'MSCI ACWI Index_monthly'!B39 -> -0.13500331 | D40: {=GEOMEAN(IF(C5:C40>0,1+B5:B40))-1} -> 0.029966242 | E40: {=GEOMEAN(IF(C5:C40>0,1+C5:C40))-1} -> 0.022995834 | F40: =(D40/E40)*100 -> 130.31161 | G40: {=GEOMEAN(IF(C5:C40<0,1+B5:B40))-1} -> -0.03953336 | H40: {=GEOMEAN(IF(C5:C40<0,1+C5:C40))-1} -> -0.053176291 | I40: =(G40/H40)*100 -> 74.34396
A41: ='MGGIX US_monthly'!A41 -> 2020-04-30 | B41: =('MGGIX US_monthly'!B41-'MGGIX US_monthly'!B40)/'MGGIX US_monthly'!B40 -> 0.12796581 | C41: =('MSCI ACWI Index_monthly'!B41-'MSCI ACWI Index_monthly'!B40)/'MSCI ACWI Index_monthly'!B40 -> 0.10712506 | D41: {=GEOMEAN(IF(C6:C41>0,1+B6:B41))-1} -> 0.033111654 | E41: {=GEOMEAN(IF(C6:C41>0,1+C6:C41))-1} -> 0.026397119 | F41: =(D41/E41)*100 -> 125.43662 | G41: {=GEOMEAN(IF(C6:C41<0,1+B6:B41))-1} -> -0.03953336 | H41: {=GEOMEAN(IF(C6:C41<0,1+C6:C41))-1} -> -0.053176291 | I41: =(G41/H41)*100 -> 74.34396
A42: ='MGGIX US_monthly'!A42 -> 2020-05-29 | B42: =('MGGIX US_monthly'!B42-'MGGIX US_monthly'!B41)/'MGGIX US_monthly'!B41 -> 0.086896568 | C42: =('MSCI ACWI Index_monthly'!B42-'MSCI ACWI Index_monthly'!B41)/'MSCI ACWI Index_monthly'!B41 -> 0.043491018 | D42: {=GEOMEAN(IF(C7:C42>0,1+B7:B42))-1} -> 0.034384209 | E42: {=GEOMEAN(IF(C7:C42>0,1+C7:C42))-1} -> 0.027215771 | F42: =(D42/E42)*100 -> 126.33928 | G42: {=GEOMEAN(IF(C7:C42<0,1+B7:B42))-1} -> -0.03953336 | H42: {=GEOMEAN(IF(C7:C42<0,1+C7:C42))-1} -> -0.053176291 | I42: =(G42/H42)*100 -> 74.34396
A43: ='MGGIX US_monthly'!A43 -> 2020-06-30 | B43: =('MGGIX US_monthly'!B43-'MGGIX US_monthly'!B42)/'MGGIX US_monthly'!B42 -> 0.073921256 | C43: =('MSCI ACWI Index_monthly'!B43-'MSCI ACWI Index_monthly'!B42)/'MSCI ACWI Index_monthly'!B42 -> 0.031952495 | D43: {=GEOMEAN(IF(C8:C43>0,1+B8:B43))-1} -> 0.037368181 | E43: {=GEOMEAN(IF(C8:C43>0,1+C8:C43))-1} -> 0.028279708 | F43: =(D43/E43)*100 -> 132.13779 | G43: {=GEOMEAN(IF(C8:C43<0,1+B8:B43))-1} -> -0.03953336 | H43: {=GEOMEAN(IF(C8:C43<0,1+C8:C43))-1} -> -0.053176291 | I43: =(G43/H43)*100 -> 74.34396
A44: ='MGGIX US_monthly'!A44 -> 2020-07-31 | B44: =('MGGIX US_monthly'!B44-'MGGIX US_monthly'!B43)/'MGGIX US_monthly'!B43 -> 0.068242289 | C44: =('MSCI ACWI Index_monthly'!B44-'MSCI ACWI Index_monthly'!B43)/'MSCI ACWI Index_monthly'!B43 -> 0.052887034 | D44: {=GEOMEAN(IF(C9:C44>0,1+B9:B44))-1} -> 0.037372179 | E44: {=GEOMEAN(IF(C9:C44>0,1+C9:C44))-1} -> 0.029228245 | F44: =(D44/E44)*100 -> 127.86323 | G44: {=GEOMEAN(IF(C9:C44<0,1+B9:B44))-1} -> -0.03953336 | H44: {=GEOMEAN(IF(C9:C44<0,1+C9:C44))-1} -> -0.053176291 | I44: =(G44/H44)*100 -> 74.34396
A45: ='MGGIX US_monthly'!A45 -> 2020-08-31 | B45: =('MGGIX US_monthly'!B45-'MGGIX US_monthly'!B44)/'MGGIX US_monthly'!B44 -> 0.11587386 | C45: =('MSCI ACWI Index_monthly'!B45-'MSCI ACWI Index_monthly'!B44)/'MSCI ACWI Index_monthly'!B44 -> 0.061205108 | D45: {=GEOMEAN(IF(C10:C45>0,1+B10:B45))-1} -> 0.041032425 | E45: {=GEOMEAN(IF(C10:C45>0,1+C10:C45))-1} -> 0.031430825 | F45: =(D45/E45)*100 -> 130.54835 | G45: {=GEOMEAN(IF(C10:C45<0,1+B10:B45))-1} -> -0.03953336 | H45: {=GEOMEAN(IF(C10:C45<0,1+C10:C45))-1} -> -0.053176291 | I45: =(G45/H45)*100 -> 74.34396
A46: ='MGGIX US_monthly'!A46 -> 2020-09-30 | B46: =('MGGIX US_monthly'!B46-'MGGIX US_monthly'!B45)/'MGGIX US_monthly'!B45 -> -0.0039653 | C46: =('MSCI ACWI Index_monthly'!B46-'MSCI ACWI Index_monthly'!B45)/'MSCI ACWI Index_monthly'!B45 -> -0.03224321 | D46: {=GEOMEAN(IF(C11:C46>0,1+B11:B46))-1} -> 0.041987903 | E46: {=GEOMEAN(IF(C11:C46>0,1+C11:C46))-1} -> 0.031918239 | F46: =(D46/E46)*100 -> 131.5483 | G46: {=GEOMEAN(IF(C11:C46<0,1+B11:B46))-1} -> -0.036353079 | H46: {=GEOMEAN(IF(C11:C46<0,1+C11:C46))-1} -> -0.051292143 | I46: =(G46/H46)*100 -> 70.874557
A47: ='MGGIX US_monthly'!A47 -> 2020-10-30 | B47: =('MGGIX US_monthly'!B47-'MGGIX US_monthly'!B46)/'MGGIX US_monthly'!B46 -> -0.019407783 | C47: =('MSCI ACWI Index_monthly'!B47-'MSCI ACWI Index_monthly'!B46)/'MSCI ACWI Index_monthly'!B46 -> -0.024308592 | D47: {=GEOMEAN(IF(C12:C47>0,1+B12:B47))-1} -> 0.042603809 | E47: {=GEOMEAN(IF(C12:C47>0,1+C12:C47))-1} -> 0.032385579 | F47: =(D47/E47)*100 -> 131.55179 | G47: {=GEOMEAN(IF(C12:C47<0,1+B12:B47))-1} -> -0.034952226 | H47: {=GEOMEAN(IF(C12:C47<0,1+C12:C47))-1} -> -0.049072305 | I47: =(G47/H47)*100 -> 71.225971
A48: ='MGGIX US_monthly'!A48 -> 2020-11-30 | B48: =('MGGIX US_monthly'!B48-'MGGIX US_monthly'!B47)/'MGGIX US_monthly'!B47 -> 0.11012434 | C48: =('MSCI ACWI Index_monthly'!B48-'MSCI ACWI Index_monthly'!B47)/'MSCI ACWI Index_monthly'!B47 -> 0.12326292 | D48: {=GEOMEAN(IF(C13:C48>0,1+B13:B48))-1} -> 0.046585788 | E48: {=GEOMEAN(IF(C13:C48>0,1+C13:C48))-1} -> 0.036569368 | F48: =(D48/E48)*100 -> 127.39019 | G48: {=GEOMEAN(IF(C13:C48<0,1+B13:B48))-1} -> -0.034952226 | H48: {=GEOMEAN(IF(C13:C48<0,1+C13:C48))-1} -> -0.049072305 | I48: =(G48/H48)*100 -> 71.225971
... A97: ='MGGIX US_monthly'!A97 -> 2024-12-31 | B97: =('MGGIX US_monthly'!B97-'MGGIX US_monthly'!B96)/'MGGIX US_monthly'!B96 -> -0.10357146 | C97: =('MSCI ACWI Index_monthly'!B97-'MSCI ACWI Index_monthly'!B96)/'MSCI ACWI Index_monthly'!B96 -> -0.023671625 | D97: {=GEOMEAN(IF(C62:C97>0,1+B62:B97))-1} -> 0.047116889 | E97: {=GEOMEAN(IF(C62:C97>0,1+C62:C97))-1} -> 0.039138372 | F97: =(D97/E97)*100 -> 120.38541 | G97: {=GEOMEAN(IF(C62:C97<0,1+B62:B97))-1} -> -0.074509829 | H97: {=GEOMEAN(IF(C62:C97<0,1+C62:C97))-1} -> -0.042245272 | I97: =(G97/H97)*100 -> 176.37436

Sheet Risk-free rate
A1: observation_date | B1: TB3MS
A2: 42736 | B2: 0.51
A3: 42767 | B3: 0.52
A4: 42795 | B4: 0.74
A5: 42826 | B5: 0.8
A6: 42856 | B6: 0.89
A7: 42887 | B7: 0.98
A8: 42917 | B8: 1.07
A9: 42948 | B9: 1.01
A10: 42979 | B10: 1.03
A11: 43009 | B11: 1.07
A12: 43040 | B12: 1.23
A13: 43070 | B13: 1.32
... A97: 45627 | B97: 4.27

Sheet MGGIX US_monthly
A1: Date | B1: NAV
A2: 2017-01-31 | B2: 16.3 | C2: =A2='MSCI ACWI Index_monthly'!A2 -> TRUE
A3: 2017-02-28 | B3: 17 | C3: =A3='MSCI ACWI Index_monthly'!A3 -> TRUE
A4: 2017-03-31 | B4: 17.86 | C4: =A4='MSCI ACWI Index_monthly'!A4 -> TRUE
A5: 2017-04-28 | B5: 18.61 | C5: =A5='MSCI ACWI Index_monthly'!A5 -> TRUE
A6: 2017-05-31 | B6: 19.59 | C6: =A6='MSCI ACWI Index_monthly'!A6 -> TRUE
A7: 2017-06-30 | B7: 19.52 | C7: =A7='MSCI ACWI Index_monthly'!A7 -> TRUE
A8: 2017-07-31 | B8: 20.85 | C8: =A8='MSCI ACWI Index_monthly'!A8 -> TRUE
A9: 2017-08-31 | B9: 21.23 | C9: =A9='MSCI ACWI Index_monthly'!A9 -> TRUE
A10: 2017-09-29 | B10: 21.6 | C10: =A10='MSCI ACWI Index_monthly'!A10 -> TRUE
A11: 2017-10-31 | B11: 22.19 | C11: =A11='MSCI ACWI Index_monthly'!A11 -> TRUE
A12: 2017-11-30 | B12: 22.48 | C12: =A12='MSCI ACWI Index_monthly'!A12 -> TRUE
A13: 2017-12-29 | B13: 22.94 | C13: =A13='MSCI ACWI Index_monthly'!A13 -> TRUE
... A97: 2024-12-31 | B97: 35.139999 | C97: =A97='MSCI ACWI Index_monthly'!A97 -> TRUE

Sheet MSCI ACWI Index_monthly
A1: Date | B1: MSCI ACWI Index
A2: 2017-01-31 | B2: 204.00496
A3: 2017-02-28 | B3: 209.72756
A4: 2017-03-31 | B4: 212.29327
A5: 2017-04-28 | B5: 215.60179
A6: 2017-05-31 | B6: 220.3629
A7: 2017-06-30 | B7: 221.36498
A8: 2017-07-31 | B8: 227.5514
A9: 2017-08-31 | B9: 228.42317
A10: 2017-09-29 | B10: 232.83631
A11: 2017-10-31 | B11: 237.67124
A12: 2017-11-30 | B12: 242.27213
A13: 2017-12-29 | B13: 246.17797
... A97: 2024-12-31 | B97: 455.98973

Sheet Metrics_Monthly (2)
A1: Date | B1: MGGIX US | C1: ACWI | D1: Return MGGIX US, Rp | E1: Return ACWI, Rm | F1: Risk-free | G1: Fund Excess | H1: Benchmark Excess | I1: Alpha | J1: Beta
A2: ='MGGIX US_monthly'!A2 -> 2017-01-31 | B2: ='MGGIX US_monthly'!B2 -> 16.3 | C2: ='MSCI ACWI Index_monthly'!B2 -> 204.00496 | F2: =(1+'Risk-free rate'!B2/100)^(1/12)-1 -> 0.00042400979
A3: ='MGGIX US_monthly'!A3 -> 2017-02-28 | B3: ='MGGIX US_monthly'!B3 -> 17 | C3: ='MSCI ACWI Index_monthly'!B3 -> 209.72756 | D3: =('MGGIX US_monthly'!B3-'MGGIX US_monthly'!B2)/'MGGIX US_monthly'!B2 -> 0.042944785 | E3: =('MSCI ACWI Index_monthly'!B3-'MSCI ACWI Index_monthly'!B2)/'MSCI ACWI Index_monthly'!B2 -> 0.028051298 | F3: =(1+'Risk-free rate'!B3/100)^(1/12)-1 -> 0.00043230397 | G3: =D3-$F3 -> 0.042512481 | H3: =E3-$F3 -> 0.027618995
A4: ='MGGIX US_monthly'!A4 -> 2017-03-31 | B4: ='MGGIX US_monthly'!B4 -> 17.86 | C4: ='MSCI ACWI Index_monthly'!B4 -> 212.29327 | D4: =('MGGIX US_monthly'!B4-'MGGIX US_monthly'!B3)/'MGGIX US_monthly'!B3 -> 0.050588235 | E4: =('MSCI ACWI Index_monthly'!B4-'MSCI ACWI Index_monthly'!B3)/'MSCI ACWI Index_monthly'!B3 -> 0.012233542 | F4: =(1+'Risk-free rate'!B4/100)^(1/12)-1 -> 0.00061458497 | G4: =D4-$F4 -> 0.04997365 | H4: =E4-$F4 -> 0.011618957
A5: ='MGGIX US_monthly'!A5 -> 2017-04-28 | B5: ='MGGIX US_monthly'!B5 -> 18.61 | C5: ='MSCI ACWI Index_monthly'!B5 -> 215.60179 | D5: =('MGGIX US_monthly'!B5-'MGGIX US_monthly'!B4)/'MGGIX US_monthly'!B4 -> 0.041993281 | E5: =('MSCI ACWI Index_monthly'!B5-'MSCI ACWI Index_monthly'!B4)/'MSCI ACWI Index_monthly'!B4 -> 0.015584667 | F5: =(1+'Risk-free rate'!B5/100)^(1/12)-1 -> 0.00066423464 | G5: =D5-$F5 -> 0.041329046 | H5: =E5-$F5 -> 0.014920432
A6: ='MGGIX US_monthly'!A6 -> 2017-05-31 | B6: ='MGGIX US_monthly'!B6 -> 19.59 | C6: ='MSCI ACWI Index_monthly'!B6 -> 220.3629 | D6: =('MGGIX US_monthly'!B6-'MGGIX US_monthly'!B5)/'MGGIX US_monthly'!B5 -> 0.05265986 | E6: =('MSCI ACWI Index_monthly'!B6-'MSCI ACWI Index_monthly'!B5)/'MSCI ACWI Index_monthly'!B5 -> 0.022082854 | F6: =(1+'Risk-free rate'!B6/100)^(1/12)-1 -> 0.00073865838 | G6: =D6-$F6 -> 0.051921202 | H6: =E6-$F6 -> 0.021344196
A7: ='MGGIX US_monthly'!A7 -> 2017-06-30 | B7: ='MGGIX US_monthly'!B7 -> 19.52 | C7: ='MSCI ACWI Index_monthly'!B7 -> 221.36498 | D7: =('MGGIX US_monthly'!B7-'MGGIX US_monthly'!B6)/'MGGIX US_monthly'!B6 -> -0.0035732517 | E7: =('MSCI ACWI Index_monthly'!B7-'MSCI ACWI Index_monthly'!B6)/'MSCI ACWI Index_monthly'!B6 -> 0.0045474443 | F7: =(1+'Risk-free rate'!B7/100)^(1/12)-1 -> 0.00081302128 | G7: =D7-$F7 -> -0.0043862729 | H7: =E7-$F7 -> 0.003734423
A8: ='MGGIX US_monthly'!A8 -> 2017-07-31 | B8: ='MGGIX US_monthly'!B8 -> 20.85 | C8: ='MSCI ACWI Index_monthly'!B8 -> 227.5514 | D8: =('MGGIX US_monthly'!B8-'MGGIX US_monthly'!B7)/'MGGIX US_monthly'!B7 -> 0.068135246 | E8: =('MSCI ACWI Index_monthly'!B8-'MSCI ACWI Index_monthly'!B7)/'MSCI ACWI Index_monthly'!B7 -> 0.027946674 | F8: =(1+'Risk-free rate'!B8/100)^(1/12)-1 -> 0.00088732345 | G8: =D8-$F8 -> 0.067247922 | H8: =E8-$F8 -> 0.02705935
A9: ='MGGIX US_monthly'!A9 -> 2017-08-31 | B9: ='MGGIX US_monthly'!B9 -> 21.23 | C9: ='MSCI ACWI Index_monthly'!B9 -> 228.42317 | D9: =('MGGIX US_monthly'!B9-'MGGIX US_monthly'!B8)/'MGGIX US_monthly'!B8 -> 0.01822542 | E9: =('MSCI ACWI Index_monthly'!B9-'MSCI ACWI Index_monthly'!B8)/'MSCI ACWI Index_monthly'!B8 -> 0.0038311124 | F9: =(1+'Risk-free rate'!B9/100)^(1/12)-1 -> 0.00083779541 | G9: =D9-$F9 -> 0.017387624 | H9: =E9-$F9 -> 0.002993317
A10: ='MGGIX US_monthly'!A10 -> 2017-09-29 | B10: ='MGGIX US_monthly'!B10 -> 21.6 | C10: ='MSCI ACWI Index_monthly'!B10 -> 232.83631 | D10: =('MGGIX US_monthly'!B10-'MGGIX US_monthly'!B9)/'MGGIX US_monthly'!B9 -> 0.017428168 | E10: =('MSCI ACWI Index_monthly'!B10-'MSCI ACWI Index_monthly'!B9)/'MSCI ACWI Index_monthly'!B9 -> 0.019320014 | F10: =(1+'Risk-free rate'!B10/100)^(1/12)-1 -> 0.00085430775 | G10: =D10-$F10 -> 0.01657386 | H10: =E10-$F10 -> 0.018465707
A11: ='MGGIX US_monthly'!A11 -> 2017-10-31 | B11: ='MGGIX US_monthly'!B11 -> 22.19 | C11: ='MSCI ACWI Index_monthly'!B11 -> 237.67124 | D11: =('MGGIX US_monthly'!B11-'MGGIX US_monthly'!B10)/'MGGIX US_monthly'!B10 -> 0.027314815 | E11: =('MSCI ACWI Index_monthly'!B11-'MSCI ACWI Index_monthly'!B10)/'MSCI ACWI Index_monthly'!B10 -> 0.020765335 | F11: =(1+'Risk-free rate'!B11/100)^(1/12)-1 -> 0.00088732345 | G11: =D11-$F11 -> 0.026427491 | H11: =E11-$F11 -> 0.019878011
A12: ='MGGIX US_monthly'!A12 -> 2017-11-30 | B12: ='MGGIX US_monthly'!B12 -> 22.48 | C12: ='MSCI ACWI Index_monthly'!B12 -> 242.27213 | D12: =('MGGIX US_monthly'!B12-'MGGIX US_monthly'!B11)/'MGGIX US_monthly'!B11 -> 0.01306895 | E12: =('MSCI ACWI Index_monthly'!B12-'MSCI ACWI Index_monthly'!B11)/'MSCI ACWI Index_monthly'!B11 -> 0.01935822 | F12: =(1+'Risk-free rate'!B12/100)^(1/12)-1 -> 0.0010192666 | G12: =D12-$F12 -> 0.012049683 | H12: =E12-$F12 -> 0.018338953
A13: ='MGGIX US_monthly'!A13 -> 2017-12-29 | B13: ='MGGIX US_monthly'!B13 -> 22.94 | C13: ='MSCI ACWI Index_monthly'!B13 -> 246.17797 | D13: =('MGGIX US_monthly'!B13-'MGGIX US_monthly'!B12)/'MGGIX US_monthly'!B12 -> 0.020462633 | E13: =('MSCI ACWI Index_monthly'!B13-'MSCI ACWI Index_monthly'!B12)/'MSCI ACWI Index_monthly'!B12 -> 0.016121714 | F13: =(1+'Risk-free rate'!B13/100)^(1/12)-1 -> 0.0010934006 | G13: =D13-$F13 -> 0.019369233 | H13: =E13-$F13 -> 0.015028313
A14: ='MGGIX US_monthly'!A14 -> 2018-01-31 | B14: ='MGGIX US_monthly'!B14 -> 24.86 | C14: ='MSCI ACWI Index_monthly'!B14 -> 260.0665 | D14: =('MGGIX US_monthly'!B14-'MGGIX US_monthly'!B13)/'MGGIX US_monthly'!B13 -> 0.0836966 | E14: =('MSCI ACWI Index_monthly'!B14-'MSCI ACWI Index_monthly'!B13)/'MSCI ACWI Index_monthly'!B13 -> 0.056416607 | F14: =(1+'Risk-free rate'!B14/100)^(1/12)-1 -> 0.0011674743 | G14: =D14-$F14 -> 0.082529126 | H14: =E14-$F14 -> 0.055249133
... A37: ='MGGIX US_monthly'!A37 -> 2019-12-31 | B37: ='MGGIX US_monthly'!B37 -> 29.120001 | C37: ='MSCI ACWI Index_monthly'!B37 -> 282.31445 | D37: =('MGGIX US_monthly'!B37-'MGGIX US_monthly'!B36)/'MGGIX US_monthly'!B36 -> 0.024630569 | E37: =('MSCI ACWI Index_monthly'!B37-'MSCI ACWI Index_monthly'!B36)/'MSCI ACWI Index_monthly'!B36 -> 0.035215218 | F37: =(1+'Risk-free rate'!B37/100)^(1/12)-1 -> 0.0012743633 | G37: =D37-$F37 -> 0.023356205 | H37: =E37-$F37 -> 0.033940854
A38: ='MGGIX US_monthly'!A38 -> 2020-01-31 | B38: ='MGGIX US_monthly'!B38 -> 29.700001 | C38: ='MSCI ACWI Index_monthly'!B38 -> 279.19603 | D38: =('MGGIX US_monthly'!B38-'MGGIX US_monthly'!B37)/'MGGIX US_monthly'!B37 -> 0.019917579 | E38: =('MSCI ACWI Index_monthly'!B38-'MSCI ACWI Index_monthly'!B37)/'MSCI ACWI Index_monthly'!B37 -> -0.011045928 | F38: =(1+'Risk-free rate'!B38/100)^(1/12)-1 -> 0.001257927 | G38: =D38-$F38 -> 0.018659652 | H38: =E38-$F38 -> -0.012303855 | I38: =((1+INDEX(LINEST(G3:G38,H3:H38,TRUE,TRUE),1,2))^12)-1 -> 0.097786501 | J38: =INDEX(LINEST(G3:G38, H3:H38, TRUE, TRUE), 1, 1) -> 1.0704536
A39: ='MGGIX US_monthly'!A39 -> 2020-02-28 | B39: ='MGGIX US_monthly'!B39 -> 28.389999 | C39: ='MSCI ACWI Index_monthly'!B39 -> 256.64542 | D39: =('MGGIX US_monthly'!B39-'MGGIX US_monthly'!B38)/'MGGIX US_monthly'!B38 -> -0.044107789 | E39: =('MSCI ACWI Index_monthly'!B39-'MSCI ACWI Index_monthly'!B38)/'MSCI ACWI Index_monthly'!B38 -> -0.080769784 | F39: =(1+'Risk-free rate'!B39/100)^(1/12)-1 -> 0.001257927 | G39: =D39-$F39 -> -0.045365716 | H39: =E39-$F39 -> -0.082027711 | I39: =((1+INDEX(LINEST(G4:G39,H4:H39,TRUE,TRUE),1,2))^12)-1 -> 0.11295594 | J39: =INDEX(LINEST(G4:G39, H4:H39, TRUE, TRUE), 1, 1) -> 1.0017097
A40: ='MGGIX US_monthly'!A40 -> 2020-03-31 | B40: ='MGGIX US_monthly'!B40 -> 25.709999 | C40: ='MSCI ACWI Index_monthly'!B40 -> 221.99744 | D40: =('MGGIX US_monthly'!B40-'MGGIX US_monthly'!B39)/'MGGIX US_monthly'!B39 -> -0.094399449 | E40: =('MSCI ACWI Index_monthly'!B40-'MSCI ACWI Index_monthly'!B39)/'MSCI ACWI Index_monthly'!B39 -> -0.13500331 | F40: =(1+'Risk-free rate'!B40/100)^(1/12)-1 -> 0.00024134605 | G40: =D40-$F40 -> -0.094640795 | H40: =E40-$F40 -> -0.13524466 | I40: =((1+INDEX(LINEST(G5:G40,H5:H40,TRUE,TRUE),1,2))^12)-1 -> 0.11462036 | J40: =INDEX(LINEST(G5:G40, H5:H40, TRUE, TRUE), 1, 1) -> 0.92950663
A41: ='MGGIX US_monthly'!A41 -> 2020-04-30 | B41: ='MGGIX US_monthly'!B41 -> 29 | C41: ='MSCI ACWI Index_monthly'!B41 -> 245.77893 | D41: =('MGGIX US_monthly'!B41-'MGGIX US_monthly'!B40)/'MGGIX US_monthly'!B40 -> 0.12796581 | E41: =('MSCI ACWI Index_monthly'!B41-'MSCI ACWI Index_monthly'!B40)/'MSCI ACWI Index_monthly'!B40 -> 0.10712506 | F41: =(1+'Risk-free rate'!B41/100)^(1/12)-1 -> 0.00011659187 | G41: =D41-$F41 -> 0.12784922 | H41: =E41-$F41 -> 0.10700847 | I41: =((1+INDEX(LINEST(G6:G41,H6:H41,TRUE,TRUE),1,2))^12)-1 -> 0.11391073 | J41: =INDEX(LINEST(G6:G41, H6:H41, TRUE, TRUE), 1, 1) -> 0.95324803
A42: ='MGGIX US_monthly'!A42 -> 2020-05-29 | B42: ='MGGIX US_monthly'!B42 -> 31.52 | C42: ='MSCI ACWI Index_monthly'!B42 -> 256.46811 | D42: =('MGGIX US_monthly'!B42-'MGGIX US_monthly'!B41)/'MGGIX US_monthly'!B41 -> 0.086896568 | E42: =('MSCI ACWI Index_monthly'!B42-'MSCI ACWI Index_monthly'!B41)/'MSCI ACWI Index_monthly'!B41 -> 0.043491018 | F42: =(1+'Risk-free rate'!B42/100)^(1/12)-1 -> 0.00010826884 | G42: =D42-$F42 -> 0.086788299 | H42: =E42-$F42 -> 0.04338275 | I42: =((1+INDEX(LINEST(G7:G42,H7:H42,TRUE,TRUE),1,2))^12)-1 -> 0.11830578 | J42: =INDEX(LINEST(G7:G42, H7:H42, TRUE, TRUE), 1, 1) -> 0.96687278
A43: ='MGGIX US_monthly'!A43 -> 2020-06-30 | B43: ='MGGIX US_monthly'!B43 -> 33.849998 | C43: ='MSCI ACWI Index_monthly'!B43 -> 264.6629 | D43: =('MGGIX US_monthly'!B43-'MGGIX US_monthly'!B42)/'MGGIX US_monthly'!B42 -> 0.073921256 | E43: =('MSCI ACWI Index_monthly'!B43-'MSCI ACWI Index_monthly'!B42)/'MSCI ACWI Index_monthly'!B42 -> 0.031952495 | F43: =(1+'Risk-free rate'!B43/100)^(1/12)-1 -> 0.00013323566 | G43: =D43-$F43 -> 0.07378802 | H43: =E43-$F43 -> 0.03181926 | I43: =((1+INDEX(LINEST(G8:G43,H8:H43,TRUE,TRUE),1,2))^12)-1 -> 0.13655576 | J43: =INDEX(LINEST(G8:G43, H8:H43, TRUE, TRUE), 1, 1) -> 0.97844146
A44: ='MGGIX US_monthly'!A44 -> 2020-07-31 | B44: ='MGGIX US_monthly'!B44 -> 36.16 | C44: ='MSCI ACWI Index_monthly'!B44 -> 278.66014 | D44: =('MGGIX US_monthly'!B44-'MGGIX US_monthly'!B43)/'MGGIX US_monthly'!B43 -> 0.068242289 | E44: =('MSCI ACWI Index_monthly'!B44-'MSCI ACWI Index_monthly'!B43)/'MSCI ACWI Index_monthly'!B43 -> 0.052887034 | F44: =(1+'Risk-free rate'!B44/100)^(1/12)-1 -> 0.00010826884 | G44: =D44-$F44 -> 0.06813402 | H44: =E44-$F44 -> 0.052778765 | I44: =((1+INDEX(LINEST(G9:G44,H9:H44,TRUE,TRUE),1,2))^12)-1 -> 0.12783552 | J44: =INDEX(LINEST(G9:G44, H9:H44, TRUE, TRUE), 1, 1) -> 0.97368396
A45: ='MGGIX US_monthly'!A45 -> 2020-08-31 | B45: ='MGGIX US_monthly'!B45 -> 40.349998 | C45: ='MSCI ACWI Index_monthly'!B45 -> 295.71556 | D45: =('MGGIX US_monthly'!B45-'MGGIX US_monthly'!B44)/'MGGIX US_monthly'!B44 -> 0.11587386 | E45: =('MSCI ACWI Index_monthly'!B45-'MSCI ACWI Index_monthly'!B44)/'MSCI ACWI Index_monthly'!B44 -> 0.061205108 | F45: =(1+'Risk-free rate'!B45/100)^(1/12)-1 -> 8.3295163e-05 | G45: =D45-$F45 -> 0.11579056 | H45: =E45-$F45 -> 0.061121813 | I45: =((1+INDEX(LINEST(G10:G45,H10:H45,TRUE,TRUE),1,2))^12)-1 -> 0.14056331 | J45: =INDEX(LINEST(G10:G45, H10:H45, TRUE, TRUE), 1, 1) -> 1.0043167
A46: ='MGGIX US_monthly'!A46 -> 2020-09-30 | B46: ='MGGIX US_monthly'!B46 -> 40.189999 | C46: ='MSCI ACWI Index_monthly'!B46 -> 286.18074 | D46: =('MGGIX US_monthly'!B46-'MGGIX US_monthly'!B45)/'MGGIX US_monthly'!B45 -> -0.0039653 | E46: =('MSCI ACWI Index_monthly'!B46-'MSCI ACWI Index_monthly'!B45)/'MSCI ACWI Index_monthly'!B45 -> -0.03224321 | F46: =(1+'Risk-free rate'!B46/100)^(1/12)-1 -> 9.1620484e-05 | G46: =D46-$F46 -> -0.0040569204 | H46: =E46-$F46 -> -0.03233483 | I46: =((1+INDEX(LINEST(G11:G46,H11:H46,TRUE,TRUE),1,2))^12)-1 -> 0.15250038 | J46: =INDEX(LINEST(G11:G46, H11:H46, TRUE, TRUE), 1, 1) -> 0.99839614
A47: ='MGGIX US_monthly'!A47 -> 2020-10-30 | B47: ='MGGIX US_monthly'!B47 -> 39.41 | C47: ='MSCI ACWI Index_monthly'!B47 -> 279.22409 | D47: =('MGGIX US_monthly'!B47-'MGGIX US_monthly'!B46)/'MGGIX US_monthly'!B46 -> -0.019407783 | E47: =('MSCI ACWI Index_monthly'!B47-'MSCI ACWI Index_monthly'!B46)/'MSCI ACWI Index_monthly'!B46 -> -0.024308592 | F47: =(1+'Risk-free rate'!B47/100)^(1/12)-1 -> 8.3295163e-05 | G47: =D47-$F47 -> -0.019491078 | H47: =E47-$F47 -> -0.024391887 | I47: =((1+INDEX(LINEST(G12:G47,H12:H47,TRUE,TRUE),1,2))^12)-1 -> 0.15164333 | J47: =INDEX(LINEST(G12:G47, H12:H47, TRUE, TRUE), 1, 1) -> 1.0017831
A48: ='MGGIX US_monthly'!A48 -> 2020-11-30 | B48: ='MGGIX US_monthly'!B48 -> 43.75 | C48: ='MSCI ACWI Index_monthly'!B48 -> 313.64207 | D48: =('MGGIX US_monthly'!B48-'MGGIX US_monthly'!B47)/'MGGIX US_monthly'!B47 -> 0.11012434 | E48: =('MSCI ACWI Index_monthly'!B48-'MSCI ACWI Index_monthly'!B47)/'MSCI ACWI Index_monthly'!B47 -> 0.12326292 | F48: =(1+'Risk-free rate'!B48/100)^(1/12)-1 -> 7.496908e-05 | G48: =D48-$F48 -> 0.11004937 | H48: =E48-$F48 -> 0.12318795 | I48: =((1+INDEX(LINEST(G13:G48,H13:H48,TRUE,TRUE),1,2))^12)-1 -> 0.15175899 | J48: =INDEX(LINEST(G13:G48, H13:H48, TRUE, TRUE), 1, 1) -> 0.97396113
A49: ='MGGIX US_monthly'!A49 -> 2020-12-31 | B49: ='MGGIX US_monthly'!B49 -> 44.75 | C49: ='MSCI ACWI Index_monthly'!B49 -> 328.2043 | D49: =('MGGIX US_monthly'!B49-'MGGIX US_monthly'!B48)/'MGGIX US_monthly'!B48 -> 0.022857143 | E49: =('MSCI ACWI Index_monthly'!B49-'MSCI ACWI Index_monthly'!B48)/'MSCI ACWI Index_monthly'!B48 -> 0.046429466 | F49: =(1+'Risk-free rate'!B49/100)^(1/12)-1 -> 7.496908e-05 | G49: =D49-$F49 -> 0.022782174 | H49: =E49-$F49 -> 0.046354497 | I49: =((1+INDEX(LINEST(G14:G49,H14:H49,TRUE,TRUE),1,2))^12)-1 -> 0.14292803 | J49: =INDEX(LINEST(G14:G49, H14:H49, TRUE, TRUE), 1, 1) -> 0.96128845
... A97: ='MGGIX US_monthly'!A97 -> 2024-12-31 | B97: ='MGGIX US_monthly'!B97 -> 35.139999 | C97: ='MSCI ACWI Index_monthly'!B97 -> 455.98973 | D97: =('MGGIX US_monthly'!B97-'MGGIX US_monthly'!B96)/'MGGIX US_monthly'!B96 -> -0.10357146 | E97: =('MSCI ACWI Index_monthly'!B97-'MSCI ACWI Index_monthly'!B96)/'MSCI ACWI Index_monthly'!B96 -> -0.023671625 | F97: =(1+'Risk-free rate'!B97/100)^(1/12)-1 -> 0.0034905364 | G97: =D97-$F97 -> -0.107062 | H97: =E97-$F97 -> -0.027162162 | I97: =((1+INDEX(LINEST(G62:G97,H62:H97,TRUE,TRUE),1,2))^12)-1 -> -0.096243336 | J97: =INDEX(LINEST(G62:G97, H62:H97, TRUE, TRUE), 1, 1) -> 1.5269357

Sheet Metrics (2)
A1: Date | B1: Return MGGIX US | C1: Return ACWI (Benchmark) | D1: Log-Return MGGIX US | E1: Rolling Vola | F1: Sharpe Ratio | G1: Rolling α | H1: Rolling β | I1: Risk-free Rate* | J1: Treynor Ratio | K1: Tracking Error
A2: 43465
A3: =LEFT(#REF!,10) -> #REF!
A4: =LEFT(#REF!,10) -> #REF! | B4: =(#REF!-#REF!)/#REF! -> #REF! | C4: =(#REF!-#REF!)/#REF! -> #REF! | D4: =LN(#REF!/#REF!) -> #REF! | E4: =_xlfn.STDEV.S(D4:D23) -> #REF! | F4: {=AVERAGE(B4:B1511-$I$4/252)/_xlfn.STDEV.S(B4:B1511-$I$4)} -> #REF! | G4: =M15-($I$4+M7*(N15-$I$4)) -> #REF! | H4: =_xlfn.COVARIANCE.S(B4:B254,C4:C254)/_xlfn.VAR.S(C4:C254) -> #REF! | I4: 0.03 | J4: =(M15-$I$4)/M7 -> #REF! | K4: {=_xlfn.STDEV.S(B4:B23-C4:C23)} -> #REF! | N4: Alpha calculated on average return
A5: =LEFT(#REF!,10) -> #REF! | B5: =(#REF!-#REF!)/#REF! -> #REF! | C5: =(#REF!-#REF!)/#REF! -> #REF! | D5: =LN(#REF!/#REF!) -> #REF! | E5: =_xlfn.STDEV.S(D5:D24) -> #REF! | F5: {=AVERAGE(B5:B1512-$I$4/252)/_xlfn.STDEV.S(B5:B1512-$I$4)} -> #REF!
A6: =LEFT(#REF!,10) -> #REF! | B6: =(#REF!-#REF!)/#REF! -> #REF! | C6: =(#REF!-#REF!)/#REF! -> #REF! | D6: =LN(#REF!/#REF!) -> #REF! | E6: =_xlfn.STDEV.S(D6:D25) -> #REF! | F6: {=AVERAGE(B6:B1513-$I$4/252)/_xlfn.STDEV.S(B6:B1513-$I$4)} -> #REF! | M6: Beta | N6: Alpha | O6: Treynor Ratio
A7: =LEFT(#REF!,10) -> #REF! | B7: =(#REF!-#REF!)/#REF! -> #REF! | C7: =(#REF!-#REF!)/#REF! -> #REF! | D7: =LN(#REF!/#REF!) -> #REF! | E7: =_xlfn.STDEV.S(D7:D26) -> #REF! | F7: {=AVERAGE(B7:B1514-$I$4/252)/_xlfn.STDEV.S(B7:B1514-$I$4)} -> #REF! | L7: 2019 | M7: =H4 -> #REF! | N7: {=252*(AVERAGE(B4:B254-((1+$I$4)^(1/252)-1))-M7*AVERAGE(C4:C254-((1+$I$4)^(1/252)-1)))} -> #REF! | O7: =(M15-$I$4)/M7 -> #REF! | Q7: =P7*252 -> 0
A8: =LEFT(#REF!,10) -> #REF! | B8: =(#REF!-#REF!)/#REF! -> #REF! | C8: =(#REF!-#REF!)/#REF! -> #REF! | D8: =LN(#REF!/#REF!) -> #REF! | E8: =_xlfn.STDEV.S(D8:D27) -> #REF! | F8: {=AVERAGE(B8:B1515-$I$4/252)/_xlfn.STDEV.S(B8:B1515-$I$4)} -> #REF! | L8: 2020 | M8: =H255 -> #REF! | N8: {=252*(AVERAGE(B255:B507-((1+$I$4)^(1/252)-1))-M8*AVERAGE(C255:C507-((1+$I$4)^(1/252)-1)))} -> #REF! | O8: =(M16-$I$4)/M8 -> #REF!
A9: =LEFT(#REF!,10) -> #REF! | B9: =(#REF!-#REF!)/#REF! -> #REF! | C9: =(#REF!-#REF!)/#REF! -> #REF! | D9: =LN(#REF!/#REF!) -> #REF! | E9: =_xlfn.STDEV.S(D9:D28) -> #REF! | F9: {=AVERAGE(B9:B1516-$I$4/252)/_xlfn.STDEV.S(B9:B1516-$I$4)} -> #REF! | L9: 2021 | M9: =H508 -> #REF! | N9: {=252*(AVERAGE(B508:B759-((1+$I$4)^(1/252)-1))-M9*AVERAGE(C508:C759-((1+$I$4)^(1/252)-1)))} -> #REF! | O9: =(M17-$I$4)/M9 -> #REF!
A10: =LEFT(#REF!,10) -> #REF! | B10: =(#REF!-#REF!)/#REF! -> #REF! | C10: =(#REF!-#REF!)/#REF! -> #REF! | D10: =LN(#REF!/#REF!) -> #REF! | E10: =_xlfn.STDEV.S(D10:D29) -> #REF! | F10: {=AVERAGE(B10:B1517-$I$4/252)/_xlfn.STDEV.S(B10:B1517-$I$4)} -> #REF! | L10: 2022 | M10: =H760 -> #REF! | N10: {=252*(AVERAGE(B760:B1010-((1+$I$4)^(1/252)-1))-M10*AVERAGE(C760:C1010-((1+$I$4)^(1/252)-1)))} -> #REF! | O10: =(M18-$I$4)/M10 -> #REF!
A11: =LEFT(#REF!,10) -> #REF! | B11: =(#REF!-#REF!)/#REF! -> #REF! | C11: =(#REF!-#REF!)/#REF! -> #REF! | D11: =LN(#REF!/#REF!) -> #REF! | E11: =_xlfn.STDEV.S(D11:D30) -> #REF! | F11: {=AVERAGE(B11:B1518-$I$4/252)/_xlfn.STDEV.S(B11:B1518-$I$4)} -> #REF! | L11: 2023 | M11: =H1011 -> #REF! | N11: {=252*(AVERAGE(B1011:B1260-((1+$I$4)^(1/252)-1))-M11*AVERAGE(C1011:C1260-((1+$I$4)^(1/252)-1)))} -> #REF! | O11: =(M19-$I$4)/M11 -> #REF!
A12: =LEFT(#REF!,10) -> #REF! | B12: =(#REF!-#REF!)/#REF! -> #REF! | C12: =(#REF!-#REF!)/#REF! -> #REF! | D12: =LN(#REF!/#REF!) -> #REF! | E12: =_xlfn.STDEV.S(D12:D31) -> #REF! | F12: {=AVERAGE(B12:B1519-$I$4/252)/_xlfn.STDEV.S(B12:B1519-$I$4)} -> #REF! | L12: 2024 | M12: =H1261 -> #REF! | N12: {=252*(AVERAGE(B1261:B1511-((1+$I$4)^(1/252)-1))-M12*AVERAGE(C1261:C1511-((1+$I$4)^(1/252)-1)))} -> #REF! | O12: =(M20-$I$4)/M12 -> #REF!
A13: =LEFT(#REF!,10) -> #REF! | B13: =(#REF!-#REF!)/#REF! -> #REF! | C13: =(#REF!-#REF!)/#REF! -> #REF! | D13: =LN(#REF!/#REF!) -> #REF! | E13: =_xlfn.STDEV.S(D13:D32) -> #REF! | F13: {=AVERAGE(B13:B1520-$I$4/252)/_xlfn.STDEV.S(B13:B1520-$I$4)} -> #REF! | M13: Yearly return
A14: =LEFT(#REF!,10) -> #REF! | B14: =(#REF!-#REF!)/#REF! -> #REF! | C14: =(#REF!-#REF!)/#REF! -> #REF! | D14: =LN(#REF!/#REF!) -> #REF! | E14: =_xlfn.STDEV.S(D14:D33) -> #REF! | F14: {=AVERAGE(B14:B1521-$I$4/252)/_xlfn.STDEV.S(B14:B1521-$I$4)} -> #REF! | M14: MGGIX US | N14: ACWI
A15: =LEFT(#REF!,10) -> #REF! | B15: =(#REF!-#REF!)/#REF! -> #REF! | C15: =(#REF!-#REF!)/#REF! -> #REF! | D15: =LN(#REF!/#REF!) -> #REF! | E15: =_xlfn.STDEV.S(D15:D34) -> #REF! | F15: {=AVERAGE(B15:B1522-$I$4/252)/_xlfn.STDEV.S(B15:B1522-$I$4)} -> #REF! | L15: 2019 | M15: =(#REF!-#REF!)/#REF! -> #REF! | N15: =(#REF!-#REF!)/#REF! -> #REF!
A16: =LEFT(#REF!,10) -> #REF! | B16: =(#REF!-#REF!)/#REF! -> #REF! | C16: =(#REF!-#REF!)/#REF! -> #REF! | D16: =LN(#REF!/#REF!) -> #REF! | E16: =_xlfn.STDEV.S(D16:D35) -> #REF! | F16: {=AVERAGE(B16:B1523-$I$4/252)/_xlfn.STDEV.S(B16:B1523-$I$4)} -> #REF! | L16: 2020 | M16: =(#REF!-#REF!)/#REF! -> #REF! | N16: =(#REF!-#REF!)/#REF! -> #REF!
A17: =LEFT(#REF!,10) -> #REF! | B17: =(#REF!-#REF!)/#REF! -> #REF! | C17: =(#REF!-#REF!)/#REF! -> #REF! | D17: =LN(#REF!/#REF!) -> #REF! | E17: =_xlfn.STDEV.S(D17:D36) -> #REF! | F17: {=AVERAGE(B17:B1524-$I$4/252)/_xlfn.STDEV.S(B17:B1524-$I$4)} -> #REF! | L17: 2021 | M17: =(#REF!-#REF!)/#REF! -> #REF! | N17: =(#REF!-#REF!)/#REF! -> #REF!
A18: =LEFT(#REF!,10) -> #REF! | B18: =(#REF!-#REF!)/#REF! -> #REF! | C18: =(#REF!-#REF!)/#REF! -> #REF! | D18: =LN(#REF!/#REF!) -> #REF! | E18: =_xlfn.STDEV.S(D18:D37) -> #REF! | F18: {=AVERAGE(B18:B1525-$I$4/252)/_xlfn.STDEV.S(B18:B1525-$I$4)} -> #REF! | L18: 2022 | M18: =(#REF!-#REF!)/#REF! -> #REF! | N18: =(#REF!-#REF!)/#REF! -> #REF!
A19: =LEFT(#REF!,10) -> #REF! | B19: =(#REF!-#REF!)/#REF! -> #REF! | C19: =(#REF!-#REF!)/#REF! -> #REF! | D19: =LN(#REF!/#REF!) -> #REF! | E19: =_xlfn.STDEV.S(D19:D38) -> #REF! | F19: {=AVERAGE(B19:B1526-$I$4/252)/_xlfn.STDEV.S(B19:B1526-$I$4)} -> #REF! | L19: 2023 | M19: =(#REF!-#REF!)/#REF! -> #REF! | N19: =(#REF!-#REF!)/#REF! -> #REF!
A20: =LEFT(#REF!,10) -> #REF! | B20: =(#REF!-#REF!)/#REF! -> #REF! | C20: =(#REF!-#REF!)/#REF! -> #REF! | D20: =LN(#REF!/#REF!) -> #REF! | E20: =_xlfn.STDEV.S(D20:D39) -> #REF! | F20: {=AVERAGE(B20:B1527-$I$4/252)/_xlfn.STDEV.S(B20:B1527-$I$4)} -> #REF! | L20: 2024 | M20: =(#REF!-#REF!)/#REF! -> #REF! | N20: =(#REF!-#REF!)/#REF! -> #REF!
A21: =LEFT(#REF!,10) -> #REF! | B21: =(#REF!-#REF!)/#REF! -> #REF! | C21: =(#REF!-#REF!)/#REF! -> #REF! | D21: =LN(#REF!/#REF!) -> #REF! | E21: =_xlfn.STDEV.S(D21:D40) -> #REF! | F21: {=AVERAGE(B21:B1528-$I$4/252)/_xlfn.STDEV.S(B21:B1528-$I$4)} -> #REF!
A22: =LEFT(#REF!,10) -> #REF! | B22: =(#REF!-#REF!)/#REF! -> #REF! | C22: =(#REF!-#REF!)/#REF! -> #REF! | D22: =LN(#REF!/#REF!) -> #REF! | E22: =_xlfn.STDEV.S(D22:D41) -> #REF! | F22: {=AVERAGE(B22:B1529-$I$4/252)/_xlfn.STDEV.S(B22:B1529-$I$4)} -> #REF!
A23: =LEFT(#REF!,10) -> #REF! | B23: =(#REF!-#REF!)/#REF! -> #REF! | C23: =(#REF!-#REF!)/#REF! -> #REF! | D23: =LN(#REF!/#REF!) -> #REF! | E23: =_xlfn.STDEV.S(D23:D42) -> #REF! | F23: {=AVERAGE(B23:B1530-$I$4/252)/_xlfn.STDEV.S(B23:B1530-$I$4)} -> #REF!
A24: =LEFT(#REF!,10) -> #REF! | B24: =(#REF!-#REF!)/#REF! -> #REF! | C24: =(#REF!-#REF!)/#REF! -> #REF! | D24: =LN(#REF!/#REF!) -> #REF! | E24: =_xlfn.STDEV.S(D24:D43) -> #REF! | F24: {=AVERAGE(B24:B1531-$I$4/252)/_xlfn.STDEV.S(B24:B1531-$I$4)} -> #REF!
A25: =LEFT(#REF!,10) -> #REF! | B25: =(#REF!-#REF!)/#REF! -> #REF! | C25: =(#REF!-#REF!)/#REF! -> #REF! | D25: =LN(#REF!/#REF!) -> #REF! | E25: =_xlfn.STDEV.S(D25:D44) -> #REF! | F25: {=AVERAGE(B25:B1532-$I$4/252)/_xlfn.STDEV.S(B25:B1532-$I$4)} -> #REF!
A26: =LEFT(#REF!,10) -> #REF! | B26: =(#REF!-#REF!)/#REF! -> #REF! | C26: =(#REF!-#REF!)/#REF! -> #REF! | D26: =LN(#REF!/#REF!) -> #REF! | E26: =_xlfn.STDEV.S(D26:D45) -> #REF! | F26: {=AVERAGE(B26:B1533-$I$4/252)/_xlfn.STDEV.S(B26:B1533-$I$4)} -> #REF!
A27: =LEFT(#REF!,10) -> #REF! | B27: =(#REF!-#REF!)/#REF! -> #REF! | C27: =(#REF!-#REF!)/#REF! -> #REF! | D27: =LN(#REF!/#REF!) -> #REF! | E27: =_xlfn.STDEV.S(D27:D46) -> #REF! | F27: {=AVERAGE(B27:B1534-$I$4/252)/_xlfn.STDEV.S(B27:B1534-$I$4)} -> #REF!
A28: =LEFT(#REF!,10) -> #REF! | B28: =(#REF!-#REF!)/#REF! -> #REF! | C28: =(#REF!-#REF!)/#REF! -> #REF! | D28: =LN(#REF!/#REF!) -> #REF! | E28: =_xlfn.STDEV.S(D28:D47) -> #REF! | F28: {=AVERAGE(B28:B1535-$I$4/252)/_xlfn.STDEV.S(B28:B1535-$I$4)} -> #REF!
A29: =LEFT(#REF!,10) -> #REF! | B29: =(#REF!-#REF!)/#REF! -> #REF! | C29: =(#REF!-#REF!)/#REF! -> #REF! | D29: =LN(#REF!/#REF!) -> #REF! | E29: =_xlfn.STDEV.S(D29:D48) -> #REF! | F29: {=AVERAGE(B29:B1536-$I$4/252)/_xlfn.STDEV.S(B29:B1536-$I$4)} -> #REF!
A30: =LEFT(#REF!,10) -> #REF! | B30: =(#REF!-#REF!)/#REF! -> #REF! | C30: =(#REF!-#REF!)/#REF! -> #REF! | D30: =LN(#REF!/#REF!) -> #REF! | E30: =_xlfn.STDEV.S(D30:D49) -> #REF! | F30: {=AVERAGE(B30:B1537-$I$4/252)/_xlfn.STDEV.S(B30:B1537-$I$4)} -> #REF!
A31: =LEFT(#REF!,10) -> #REF! | B31: =(#REF!-#REF!)/#REF! -> #REF! | C31: =(#REF!-#REF!)/#REF! -> #REF! | D31: =LN(#REF!/#REF!) -> #REF! | E31: =_xlfn.STDEV.S(D31:D50) -> #REF! | F31: {=AVERAGE(B31:B1538-$I$4/252)/_xlfn.STDEV.S(B31:B1538-$I$4)} -> #REF!
A32: =LEFT(#REF!,10) -> #REF! | B32: =(#REF!-#REF!)/#REF! -> #REF! | C32: =(#REF!-#REF!)/#REF! -> #REF! | D32: =LN(#REF!/#REF!) -> #REF! | E32: =_xlfn.STDEV.S(D32:D51) -> #REF! | F32: {=AVERAGE(B32:B1539-$I$4/252)/_xlfn.STDEV.S(B32:B1539-$I$4)} -> #REF!
... A254: =LEFT(#REF!,10) -> #REF! | B254: =(#REF!-#REF!)/#REF! -> #REF! | C254: =(#REF!-#REF!)/#REF! -> #REF! | D254: =LN(#REF!/#REF!) -> #REF! | E254: =_xlfn.STDEV.S(D254:D273) -> #REF! | F254: {=AVERAGE(B254:B1761-$I$4/252)/_xlfn.STDEV.S(B254:B1761-$I$4)} -> #REF!
A255: =LEFT(#REF!,10) -> #REF! | B255: =(#REF!-#REF!)/#REF! -> #REF! | C255: =(#REF!-#REF!)/#REF! -> #REF! | D255: =LN(#REF!/#REF!) -> #REF! | E255: =_xlfn.STDEV.S(D255:D274) -> #REF! | F255: {=AVERAGE(B255:B1762-$I$4/252)/_xlfn.STDEV.S(B255:B1762-$I$4)} -> #REF! | G255: =M16-($I$4+M8*(N16-$I$4)) -> #REF! | H255: =_xlfn.COVARIANCE.S(B255:B507,C255:C507)/_xlfn.VAR.S(C255:C507) -> #REF! | J255: =(M16-$I$4)/M8 -> #REF!
A256: =LEFT(#REF!,10) -> #REF! | B256: =(#REF!-#REF!)/#REF! -> #REF! | C256: =(#REF!-#REF!)/#REF! -> #REF! | D256: =LN(#REF!/#REF!) -> #REF! | E256: =_xlfn.STDEV.S(D256:D275) -> #REF! | F256: {=AVERAGE(B256:B1763-$I$4/252)/_xlfn.STDEV.S(B256:B1763-$I$4)} -> #REF!
A257: =LEFT(#REF!,10) -> #REF! | B257: =(#REF!-#REF!)/#REF! -> #REF! | C257: =(#REF!-#REF!)/#REF! -> #REF! | D257: =LN(#REF!/#REF!) -> #REF! | E257: =_xlfn.STDEV.S(D257:D276) -> #REF! | F257: {=AVERAGE(B257:B1764-$I$4/252)/_xlfn.STDEV.S(B257:B1764-$I$4)} -> #REF!
A258: =LEFT(#REF!,10) -> #REF! | B258: =(#REF!-#REF!)/#REF! -> #REF! | C258: =(#REF!-#REF!)/#REF! -> #REF! | D258: =LN(#REF!/#REF!) -> #REF! | E258: =_xlfn.STDEV.S(D258:D277) -> #REF! | F258: {=AVERAGE(B258:B1765-$I$4/252)/_xlfn.STDEV.S(B258:B1765-$I$4)} -> #REF!
A259: =LEFT(#REF!,10) -> #REF! | B259: =(#REF!-#REF!)/#REF! -> #REF! | C259: =(#REF!-#REF!)/#REF! -> #REF! | D259: =LN(#REF!/#REF!) -> #REF! | E259: =_xlfn.STDEV.S(D259:D278) -> #REF! | F259: {=AVERAGE(B259:B1766-$I$4/252)/_xlfn.STDEV.S(B259:B1766-$I$4)} -> #REF!
A260: =LEFT(#REF!,10) -> #REF! | B260: =(#REF!-#REF!)/#REF! -> #REF! | C260: =(#REF!-#REF!)/#REF! -> #REF! | D260: =LN(#REF!/#REF!) -> #REF! | E260: =_xlfn.STDEV.S(D260:D279) -> #REF! | F260: {=AVERAGE(B260:B1767-$I$4/252)/_xlfn.STDEV.S(B260:B1767-$I$4)} -> #REF!
A261: =LEFT(#REF!,10) -> #REF! | B261: =(#REF!-#REF!)/#REF! -> #REF! | C261: =(#REF!-#REF!)/#REF! -> #REF! | D261: =LN(#REF!/#REF!) -> #REF! | E261: =_xlfn.STDEV.S(D261:D280) -> #REF! | F261: {=AVERAGE(B261:B1768-$I$4/252)/_xlfn.STDEV.S(B261:B1768-$I$4)} -> #REF!
...

Sheet Metrics_Yearly (2)
B1: Yearly return MGGIX US, Rp | C1: Yearly return ACWI, Rm | D1: Risk-free Rate, Rf | E1: Beta | F1: Alpha | G1: Sharpe Ratio | H1: Treynor Ratio | I1: Tracking Error
A2: 2019 | B2: =(#REF!-#REF!)/#REF! -> #REF! | C2: =(#REF!-#REF!)/#REF! -> #REF! | D2: 0.0206 | E2: =_xlfn.COVARIANCE.S(#REF!,#REF!)/_xlfn.VAR.S(#REF!) -> #REF! | F2: =B2-(D2+E2*(C2-D2)) -> #REF! | G2: =(AVERAGE(#REF!)-('Metrics_Yearly (2)'!D2/252))/_xlfn.STDEV.S(#REF!)*SQRT(252) -> #REF! | H2: =(B2-D2)/E2 -> #REF! | I2: =_xlfn.STDEV.S(#REF!)*SQRT(252) -> #REF!
A3: 2020 | B3: =(#REF!-#REF!)/#REF! -> #REF! | C3: =(#REF!-#REF!)/#REF! -> #REF! | D3: 0.0035 | E3: =_xlfn.COVARIANCE.S(#REF!,#REF!)/_xlfn.VAR.S(#REF!) -> #REF! | F3: =B3-(D3+E3*(C3-D3)) -> #REF! | G3: =(AVERAGE(#REF!)-('Metrics_Yearly (2)'!D3/252))/_xlfn.STDEV.S(#REF!)*SQRT(252) -> #REF! | H3: =(B3-D3)/E3 -> #REF! | I3: =_xlfn.STDEV.S(#REF!)*SQRT(252) -> #REF!
A4: 2021 | B4: =(#REF!-#REF!)/#REF! -> #REF! | C4: =(#REF!-#REF!)/#REF! -> #REF! | D4: 0.0004 | E4: =_xlfn.COVARIANCE.S(#REF!,#REF!)/_xlfn.VAR.S(#REF!) -> #REF! | F4: =B4-(D4+E4*(C4-D4)) -> #REF! | G4: =(AVERAGE(#REF!)-('Metrics_Yearly (2)'!D4/252))/_xlfn.STDEV.S(#REF!)*SQRT(252) -> #REF! | H4: =(B4-D4)/E4 -> #REF! | I4: =_xlfn.STDEV.S(#REF!)*SQRT(252) -> #REF!
A5: 2022 | B5: =(#REF!-#REF!)/#REF! -> #REF! | C5: =(#REF!-#REF!)/#REF! -> #REF! | D5: 0.0202 | E5: =_xlfn.COVARIANCE.S(#REF!,#REF!)/_xlfn.VAR.S(#REF!) -> #REF! | F5: =B5-(D5+E5*(C5-D5)) -> #REF! | G5: =(AVERAGE(#REF!)-('Metrics_Yearly (2)'!D5/252))/_xlfn.STDEV.S(#REF!)*SQRT(252) -> #REF! | H5: =(B5-D5)/E5 -> #REF! | I5: =_xlfn.STDEV.S(#REF!)*SQRT(252) -> #REF!
A6: 2023 | B6: =(#REF!-#REF!)/#REF! -> #REF! | C6: =(#REF!-#REF!)/#REF! -> #REF! | D6: 0.0507 | E6: =_xlfn.COVARIANCE.S(#REF!,#REF!)/_xlfn.VAR.S(#REF!) -> #REF! | F6: =B6-(D6+E6*(C6-D6)) -> #REF! | G6: =(AVERAGE(#REF!)-('Metrics_Yearly (2)'!D6/252))/_xlfn.STDEV.S(#REF!)*SQRT(252) -> #REF! | H6: =(B6-D6)/E6 -> #REF! | I6: =_xlfn.STDEV.S(#REF!)*SQRT(252) -> #REF!
A7: 2024 | B7: =(#REF!-#REF!)/#REF! -> #REF! | C7: =(#REF!-#REF!)/#REF! -> #REF! | D7: 0.0525 | E7: =_xlfn.COVARIANCE.S(#REF!,#REF!)/_xlfn.VAR.S(#REF!) -> #REF! | F7: =B7-(D7+E7*(C7-D7)) -> #REF! | G7: =(AVERAGE(#REF!)-('Metrics_Yearly (2)'!D7/252))/_xlfn.STDEV.S(#REF!)*SQRT(252) -> #REF! | H7: =(B7-D7)/E7 -> #REF! | I7: =_xlfn.STDEV.S(#REF!)*SQRT(252) -> #REF!
A9: check
B10: =#REF! -> #REF! | C10: =#REF! -> #REF! | E10: =#REF! -> #REF! | F10: =#REF! -> #REF! | H10: =#REF! -> #REF! | I10: =#REF! -> #REF!
B11: =#REF! -> #REF! | C11: =#REF! -> #REF! | E11: =#REF! -> #REF! | F11: =#REF! -> #REF! | H11: =#REF! -> #REF! | I11: =#REF! -> #REF!
B12: =#REF! -> #REF! | C12: =#REF! -> #REF! | E12: =#REF! -> #REF! | F12: =#REF! -> #REF! | H12: =#REF! -> #REF! | I12: =#REF! -> #REF!
B13: =#REF! -> #REF! | C13: =#REF! -> #REF! | E13: =#REF! -> #REF! | F13: =#REF! -> #REF! | H13: =#REF! -> #REF! | I13: =#REF! -> #REF!
B14: =#REF! -> #REF! | C14: =#REF! -> #REF! | E14: =#REF! -> #REF! | F14: =#REF! -> #REF! | H14: =#REF! -> #REF! | I14: =#REF! -> #REF!
B15: =#REF! -> #REF! | C15: =#REF! -> #REF! | E15: =#REF! -> #REF! | F15: =#REF! -> #REF! | H15: =#REF! -> #REF! | I15: =#REF! -> #REF!
B17: =B10=B2 -> #REF! | C17: =C10=C2 -> #REF! | E17: =E10=E2 -> #REF! | F17: =F10=F2 -> #REF! | H17: =H10=H2 -> #REF! | I17: =I10=I2 -> #REF!
B18: =B11=B3 -> #REF! | C18: =C11=C3 -> #REF! | E18: =E11=E3 -> #REF! | F18: =F11=F3 -> #REF! | H18: =H11=H3 -> #REF! | I18: =I11=I3 -> #REF!
B19: =B12=B4 -> #REF! | C19: =C12=C4 -> #REF! | E19: =E12=E4 -> #REF! | F19: =F12=F4 -> #REF! | H19: =H12=H4 -> #REF! | I19: =I12=I4 -> #REF!
B20: =B13=B5 -> #REF! | C20: =C13=C5 -> #REF! | E20: =E13=E5 -> #REF! | F20: =F13=F5 -> #REF! | H20: =H13=H5 -> #REF! | I20: =I13=I5 -> #REF!
B21: =B14=B6 -> #REF! | C21: =C14=C6 -> #REF! | E21: =E14=E6 -> #REF! | F21: =F14=F6 -> #REF! | H21: =H14=H6 -> #REF! | I21: =I14=I6 -> #REF!
B22: =B15=B7 -> #REF! | C22: =C15=C7 -> #REF! | E22: =E15=E7 -> #REF! | F22: =F15=F7 -> #REF! | H22: =H15=H7 -> #REF! | I22: =I15=I7 -> #REF!
